<?xml version="1.0"?>
<!--
    CALIBRATED real_pantilt URDF
    Generated by ptu_calib_cpp
    Pan  encoder zero offset: 0.001108 rad (0.063498 deg)
    Tilt encoder zero offset: 0.091797 rad (5.259582 deg)
-->
<robot name="real_pantilt" xmlns:xacro="http://ros.org/wiki/xacro">

    <link name="map">
        <inertial>
            <mass value="0.001" />
            <origin xyz="0 0 0" rpy="0 0 0" />
            <inertia ixx="0.0001" ixy="0" ixz="0" iyy="0.0001" iyz="0" izz="0.0001" />
        </inertial>
    </link>

    <link name="base_link">
        <visual>
            <origin xyz="0.0 -0.05 0.035" rpy="0 0 0" />
            <geometry><box size="0.0625 0.095 0.07" /></geometry>
            <material name="Cyan1"><color rgba="0 0.9 0.9 1.0" /></material>
        </visual>
        <inertial>
            <mass value="1" />
            <origin xyz="0 0 0" rpy="0 0 0" />
            <inertia ixx="0.01" ixy="0" ixz="0" iyy="0.01" iyz="0" izz="0.01" />
        </inertial>
    </link>

    <joint name="map_to_base" type="fixed">
        <origin xyz="0 0 0" rpy="0 0 0" />
        <parent link="map" />
        <child link="base_link" />
    </joint>

    <link name="pan_link">
        <visual>
            <origin xyz="0 0 0" rpy="0 0 0" />
            <geometry><box size="0.035 0.038 0.044" /></geometry>
            <material name="Yellow2"><color rgba="0.8 0.8 0 1.0" /></material>
        </visual>
        <inertial>
            <mass value="0.50" />
            <origin xyz="0 0 0" rpy="0 0 0" />
            <inertia ixx="0.01" ixy="0" ixz="0" iyy="0.01" iyz="0" izz="0.01" />
        </inertial>
    </link>

    <!-- CALIBRATED joint2 (pan): base_link -> pan_link -->
    <joint name="joint2" type="revolute">
        <parent link="base_link" />
        <child link="pan_link" />
        <origin xyz="0.000000 -0.025500 0.095000"
                rpy="0.052360 0.000860 -0.001166" />
        <axis xyz="0 0 -1" />
        <limit effort="10" lower="-3.1416" upper="3.1416" velocity="3" />
        <dynamics damping="1.0" />
    </joint>

    <link name="tilt_link">
        <visual>
            <origin xyz="-0.022 0 0" rpy="0 -1.57 0" />
            <geometry><box size="0.005 0.005 0.044" /></geometry>
            <material name="Cyan1"><color rgba="0 0.9 0.9 1.0" /></material>
        </visual>
        <inertial>
            <mass value="0.20" />
            <origin xyz="0 0 0" rpy="0 0 0" />
            <inertia ixx="0.01" ixy="0" ixz="0" iyy="0.01" iyz="0" izz="0.01" />
        </inertial>
    </link>

    <!-- CALIBRATED joint1 (tilt): pan_link -> tilt_link -->
    <!-- NOTE: nominal pitch~pi/2 => RPY is near gimbal lock; values are correct -->
    <!-- Corrections: dt=(-0.000373, 0.002930, -0.000000)m  dr=(2.545179, 0.279720, 3.000000)deg -->
    <joint name="joint1" type="revolute">
        <parent link="pan_link" />
        <child link="tilt_link" />
        <origin xyz="-0.000001 -0.006070 0.022373"
                rpy="1.693000 1.518278 1.648727" />
        <axis xyz="0 0 1" />
        <limit effort="10" lower="-0.8727" upper="0.8727" velocity="3" />
        <dynamics damping="1.0" />
    </joint>

    <link name="laser">
        <visual>
            <origin xyz="0.0 0.0 -0.059" rpy="1.57 0 0" />
            <geometry>
                <mesh filename="/home/isl9/dev/mert/hokuyo_ws/src/hokuyo_go/urdf/meshes/URG-04LX.dae" scale="0.001 0.001 0.001" />
            </geometry>
            <material name="Cyan1"><color rgba="0 0.9 0.9 1.0" /></material>
        </visual>
        <inertial>
            <mass value="0.16" />
            <origin xyz="0 0 0" rpy="0 0 0" />
            <inertia ixx="0.001" ixy="0" ixz="0" iyy="0.001" iyz="0" izz="0.001" />
        </inertial>
    </link>

    <!-- CALIBRATED laser mount: tilt_link -> laser (collapsed from hokuyo_base_joint + hokuyo_joint) -->
    <joint name="hokuyo_joint" type="fixed">
        <parent link="tilt_link" />
        <child link="laser" />
        <origin xyz="-0.106000 0.014000 0.040000"
                rpy="-1.571593 0.001593 1.571593" />
        <dynamics damping="1.0" />
    </joint>

</robot>
