<?xml version="1.0"?>
<!--
    CALIBRATED real_pantilt URDF
    Generated by ptu_calib_cpp
    Pan  encoder zero offset: 0.139626 rad (8.000000 deg)
    Tilt encoder zero offset: 0.079793 rad (4.571794 deg)
-->
<robot name="real_pantilt" xmlns:xacro="http://ros.org/wiki/xacro">

    <link name="map">
        <inertial>
            <mass value="0.001" />
            <origin xyz="0 0 0" rpy="0 0 0" />
            <inertia ixx="0.0001" ixy="0" ixz="0" iyy="0.0001" iyz="0" izz="0.0001" />
        </inertial>
    </link>

    <link name="base_link">
        <visual>
            <origin xyz="0.0 -0.05 0.035" rpy="0 0 0" />
            <geometry><box size="0.0625 0.095 0.07" /></geometry>
            <material name="Cyan1"><color rgba="0 0.9 0.9 1.0" /></material>
        </visual>
        <inertial>
            <mass value="1" />
            <origin xyz="0 0 0" rpy="0 0 0" />
            <inertia ixx="0.01" ixy="0" ixz="0" iyy="0.01" iyz="0" izz="0.01" />
        </inertial>
    </link>

    <joint name="map_to_base" type="fixed">
        <origin xyz="0 0 0" rpy="0 0 0" />
        <parent link="map" />
        <child link="base_link" />
    </joint>

    <link name="pan_link">
        <visual>
            <origin xyz="0 0 0" rpy="0 0 0" />
            <geometry><box size="0.035 0.038 0.044" /></geometry>
            <material name="Yellow2"><color rgba="0.8 0.8 0 1.0" /></material>
        </visual>
        <inertial>
            <mass value="0.50" />
            <origin xyz="0 0 0" rpy="0 0 0" />
            <inertia ixx="0.01" ixy="0" ixz="0" iyy="0.01" iyz="0" izz="0.01" />
        </inertial>
    </link>

    <!-- CALIBRATED joint2 (pan): base_link -> pan_link -->
    <joint name="joint2" type="revolute">
        <parent link="base_link" />
        <child link="pan_link" />
        <origin xyz="0.000000 -0.030500 0.090000"
                rpy="0.034907 0.034907 -0.034907" />
        <axis xyz="0 0 -1" />
        <limit effort="10" lower="-3.1416" upper="3.1416" velocity="3" />
        <dynamics damping="1.0" />
    </joint>

    <link name="tilt_link">
        <visual>
            <origin xyz="-0.022 0 0" rpy="0 -1.57 0" />
            <geometry><box size="0.005 0.005 0.044" /></geometry>
            <material name="Cyan1"><color rgba="0 0.9 0.9 1.0" /></material>
        </visual>
        <inertial>
            <mass value="0.20" />
            <origin xyz="0 0 0" rpy="0 0 0" />
            <inertia ixx="0.01" ixy="0" ixz="0" iyy="0.01" iyz="0" izz="0.01" />
        </inertial>
    </link>

    <!-- CALIBRATED joint1 (tilt): pan_link -> tilt_link -->
    <joint name="joint1" type="revolute">
        <parent link="pan_link" />
        <child link="tilt_link" />
        <origin xyz="0.000028 -0.011000 0.020879"
                rpy="2.321494 1.524529 2.287145" />
        <axis xyz="0 0 1" />
        <limit effort="10" lower="-0.8727" upper="0.8727" velocity="3" />
        <dynamics damping="1.0" />
    </joint>

    <link name="laser">
        <visual>
            <origin xyz="0.0 0.0 -0.059" rpy="1.57 0 0" />
            <geometry>
                <mesh filename="/home/isl9/dev/mert/hokuyo_ws/src/hokuyo_go/urdf/meshes/URG-04LX.dae" scale="0.001 0.001 0.001" />
            </geometry>
            <material name="Cyan1"><color rgba="0 0.9 0.9 1.0" /></material>
        </visual>
        <inertial>
            <mass value="0.16" />
            <origin xyz="0 0 0" rpy="0 0 0" />
            <inertia ixx="0.001" ixy="0" ixz="0" iyy="0.001" iyz="0" izz="0.001" />
        </inertial>
    </link>

    <!-- CALIBRATED laser mount: tilt_link -> laser (collapsed from hokuyo_base_joint + hokuyo_joint) -->
    <joint name="hokuyo_joint" type="fixed">
        <parent link="tilt_link" />
        <child link="laser" />
        <origin xyz="-0.105989 0.012000 0.040280"
                rpy="-1.571548 -0.033314 1.571110" />
        <dynamics damping="1.0" />
    </joint>

</robot>
