<?xml version="1.0"?>
<!--
    NOMINAL (ground truth) pan-tilt URDF.
    This is the "correct" model that the solver should converge to.
    Straight from the original real_pantilt URDF with no calibration.
-->
<robot name="real_pantilt" xmlns:xacro="http://ros.org/wiki/xacro">

    <link name="map">
        <inertial>
            <mass value="0.001" />
            <origin xyz="0 0 0" rpy="0 0 0" />
            <inertia ixx="0.0001" ixy="0" ixz="0" iyy="0.0001" iyz="0" izz="0.0001" />
        </inertial>
    </link>

    <link name="base_link">
        <visual>
            <origin xyz="0.0 -0.05 0.035" rpy="0 0 0" />
            <geometry><box size="0.0625 0.095 0.07" /></geometry>
            <material name="Cyan1"><color rgba="0 0.9 0.9 1.0" /></material>
        </visual>
        <collision>
            <origin xyz="0.0 -0.05 0.035" rpy="0 0 0" />
            <geometry><box size="0.0625 0.095 0.07" /></geometry>
        </collision>
        <inertial>
            <mass value="1" />
            <origin xyz="0 0 0" rpy="0 0 0" />
            <inertia ixx="0.01" ixy="0" ixz="0" iyy="0.01" iyz="0" izz="0.01" />
        </inertial>
    </link>

    <joint name="map_to_base" type="fixed">
        <origin xyz="0 0 0" rpy="0 0 0" />
        <parent link="map" />
        <child link="base_link" />
    </joint>

    <link name="pan_link">
        <visual>
            <origin xyz="0 0 0" rpy="0 0 0" />
            <geometry><box size="0.035 0.038 0.044" /></geometry>
            <material name="Yellow2"><color rgba="0.8 0.8 0 1.0" /></material>
        </visual>
        <collision>
            <origin xyz="0 0 0" rpy="0 0 0" />
            <geometry><box size="0.035 0.038 0.044" /></geometry>
        </collision>
        <inertial>
            <mass value="0.50" />
            <origin xyz="0 0 0" rpy="0 0 0" />
            <inertia ixx="0.01" ixy="0" ixz="0" iyy="0.01" iyz="0" izz="0.01" />
        </inertial>
    </link>

    <!-- joint2 (pan): NOMINAL values -->
    <joint name="joint2" type="revolute">
        <parent link="base_link" />
        <child link="pan_link" />
        <origin xyz="0 -0.0285 0.092" rpy="0 0 0" />
        <axis xyz="0 0 -1" />
        <limit effort="10" lower="-3.1416" upper="3.1416" velocity="3" />
        <dynamics damping="1.0" />
    </joint>

    <link name="tilt_link">
        <visual>
            <origin xyz="-0.022 0 0" rpy="0 -1.57 0" />
            <geometry><box size="0.005 0.005 0.044" /></geometry>
            <material name="Cyan1"><color rgba="0 0.9 0.9 1.0" /></material>
        </visual>
        <collision>
            <origin xyz="-0.022 0 0" rpy="0 -1.57 0" />
            <geometry><box size="0.005 0.005 0.044" /></geometry>
        </collision>
        <inertial>
            <mass value="0.20" />
            <origin xyz="0 0 0" rpy="0 0 0" />
            <inertia ixx="0.01" ixy="0" ixz="0" iyy="0.01" iyz="0" izz="0.01" />
        </inertial>
    </link>

    <!-- joint1 (tilt): NOMINAL values -->
    <joint name="joint1" type="revolute">
        <parent link="pan_link" />
        <child link="tilt_link" />
        <origin xyz="0 -0.009 0.022" rpy="0 1.57 0" />
        <axis xyz="0 0 1" />
        <limit effort="10" lower="-0.8727" upper="0.8727" velocity="3" />
        <dynamics damping="1.0" />
    </joint>

    <link name="hokuyo_base">
        <visual>
            <origin xyz="0 0 0" rpy="0 -1.57 0" />
            <geometry><box size="0.162 0.06 0.003" /></geometry>
            <material name="Yellow2"><color rgba="0.8 0.8 0 1.0" /></material>
        </visual>
        <collision>
            <origin xyz="0 0 0" rpy="0 -1.57 0" />
            <geometry><box size="0.162 0.06 0.003" /></geometry>
        </collision>
        <inertial>
            <mass value="0.10" />
            <origin xyz="0 0 0" rpy="0 0 0" />
            <inertia ixx="0.01" ixy="0" ixz="0" iyy="0.01" iyz="0" izz="0.01" />
        </inertial>
    </link>

    <joint name="hokuyo_base_joint" type="fixed">
        <parent link="tilt_link" />
        <child link="hokuyo_base" />
        <origin xyz="-0.045 0 0" rpy="0 0 0" />
        <dynamics damping="1.0" />
    </joint>

    <link name="laser">
        <visual>
            <origin xyz="0.0 0.0 -0.059" rpy="1.57 0 0" />
            <geometry>
                <box size="0.05 0.05 0.07" />
            </geometry>
            <material name="Cyan1"><color rgba="0 0.9 0.9 1.0" /></material>
        </visual>
        <collision>
            <origin xyz="0.0 0.0 -0.059" rpy="1.57 0 0" />
            <geometry>
                <box size="0.05 0.05 0.07" />
            </geometry>
        </collision>
        <inertial>
            <mass value="0.16" />
            <origin xyz="0 0 0" rpy="0 0 0" />
            <inertia ixx="0.001" ixy="0" ixz="0" iyy="0.001" iyz="0" izz="0.001" />
        </inertial>
    </link>

    <joint name="hokuyo_joint" type="fixed">
        <origin xyz="-0.061 0.014 0.040" rpy="1.57 3.14 -1.57" />
        <parent link="hokuyo_base" />
        <child link="laser" />
        <dynamics damping="1.0" />
    </joint>

    <!-- =================== GAZEBO EXTENSIONS =================== -->

    <!-- Hokuyo planar lidar plugin (same as real URG-04LX) -->
    <gazebo reference="laser">
        <sensor type="ray" name="hokuyo_sensor">
            <pose>0 0 0 0 0 0</pose>
            <visualize>true</visualize>
            <update_rate>10</update_rate>
            <ray>
                <scan>
                    <horizontal>
                        <samples>683</samples>
                        <resolution>1</resolution>
                        <min_angle>-2.0944</min_angle>
                        <max_angle>2.0944</max_angle>
                    </horizontal>
                </scan>
                <range>
                    <min>0.06</min>
                    <max>4.095</max>
                    <resolution>0.001</resolution>
                </range>
                <noise>
                    <type>gaussian</type>
                    <mean>0.0</mean>
                    <stddev>0.001</stddev>
                </noise>
            </ray>
            <plugin name="gazebo_ros_hokuyo" filename="libgazebo_ros_laser.so">
                <topicName>/scan</topicName>
                <frameName>laser</frameName>
            </plugin>
        </sensor>
    </gazebo>

    <!-- Fix robot to world -->
    <gazebo>
        <static>false</static>
    </gazebo>
    <gazebo reference="map">
        <static>true</static>
    </gazebo>

    <!-- Low-friction joints for position control -->
    <gazebo reference="joint2">
        <implicitSpringDamper>true</implicitSpringDamper>
    </gazebo>
    <gazebo reference="joint1">
        <implicitSpringDamper>true</implicitSpringDamper>
    </gazebo>

</robot>
